Workbook
Name ActualInvestment: LongTerm!#REF!
Name ActualInvestment: Asset!#REF!
Name avgExpense: DashBoard!$D$27
Name avgIncome: DashBoard!$C$27
Name AvgInvestment: DashBoard!$F$27
Name avgLoanRePayment: DashBoard!$E$27
Name AvgSavings: DashBoard!$G$27
Name BasicSalary: Income!$C$2
Name CurrentMonth: DashBoard!$F$1
Name ExpenseAvg: Expenses!$C$12
Name IncomeAvg: Income!$D$11
Name IntraDayLCount: [1]Ledger!$U$2
Name IntraDayLearnPer: [1]Ledger!$Y$2
Name IntraDayProfit: [1]Ledger!$W$2
Name IntraDayProfitPer: [1]Ledger!$X$2
Name IntraDaySCount: [1]Ledger!$T$2
Name InvestmentAvg: Investment!$C$14
Name InvestmentCurrValue: LongTerm!#REF!
Name InvestmentCurrValue: Asset!#REF!
Name InvestmentProfit: LongTerm!#REF!
Name InvestmentProfit: Asset!#REF!
Name InvestmentQuota: Investment!$C$3
Name INVQuota: Asset!#REF!
Name INVQuota: LongTerm!#REF!
Name INVQuota: #REF!
Name LoanAvg: Loan!$D$13
Name LongTermQuota: Corpus!$F$17
Name StockPortfolioValue: Corpus!$K$4
Name StocksWallet: Investment!$A$3
Name SummartTable: Table3[#All]
Name SummartTable: Table3[#All]
Name SwingInvestment: [1]Ledger!#REF!
Name SwingOpenOrder: [1]Ledger!$Z$3
Name SwingProfit: [1]Ledger!$W$3
Name SwingTradeQuota: Corpus!$F$19
Name TotalInvestment: LongTerm!#REF!
Name TotalInvestment: Asset!#REF!
Name TotalMonth: DashBoard!$H$1
Name TradingFund: LongTerm!#REF!
Name TradingFund: Asset!#REF!
Name TradingQuota: LongTerm!#REF!
Name TradingQuota: Asset!#REF!

Sheet DashBoard
D1: 💼💰 | E1: 📊 DashBoard as of | F1: =DATE(YEAR(TODAY()), MONTH(TODAY()), 1) -> 46113 | G1: 🗓️📈 | H1: =DATEDIF(DATE(2025,10,1), TODAY(), "m") -> 6
B3: 💰⬆️Avg Income | D3: =avgIncome -> 273927.8 | F3: 📈💼Avg Investment | H3: =AvgInvestment -> 98363
B4: 💸⬇️Avg Expense | D4: =avgExpense -> 97550 | F4: 🐖💰Avg Savings | H4: =AvgSavings -> -53299
B5: 🏦🔁Avg Loan Repayment | D5: =avgLoanRePayment -> 166910.2 | F5: 🏛️RBI Balance | H5: =INDEX(RBITable[Transactions], MATCH(CurrentMonth,RBITable[Month],0)) -> 0
B9: 📊 70% of Investment 🚀 | D9: 🪙10% of Investment✨ | E9: 👴14% of Basic Salary📈 | F9: 🎯20% of Investment💸 | H9: 🏠No Allocation So far 📊
A10: 🗂️ | B10: Equity | D10: Gold | E10: Retirement | F10: Fixed Return | H10: Real State
A11: 🎯 | B11: =_xlfn.CEILING.MATH(avgIncome*30%*70%) -> 57525 | D11: =_xlfn.CEILING.MATH(avgIncome*30%*10%) -> 8218 | E11: =_xlfn.CEILING.MATH(15515) -> 15515 | F11: =_xlfn.CEILING.MATH(avgIncome*30%*20%) -> 16436 | H11: =_xlfn.CEILING.MATH(avgIncome*0%) -> 0
A12: ✅ | B12: =AVERAGE(Investment!D14:E14) -> 1859 | D12: =AVERAGEIF(Investment!F14:I14,">0") -> 4405.5 | E12: =Investment!K14 -> 15515 | F12: =Investment!L14 -> 12500
A13: 💰 | B13: =SUMIFS(CorpusTable[Invested],CorpusTable[Type],DashBoard!B10) -> 2829087 | D13: =SUMIFS(CorpusTable[Invested],CorpusTable[Type],DashBoard!D10) -> 422438 | E13: =SUMIFS(CorpusTable[Invested],CorpusTable[Type],DashBoard!E10) -> 1040101 | F13: =SUMIFS(CorpusTable[Invested],CorpusTable[Type],DashBoard!F10) -> 2699100 | H13: =SUMIFS(CorpusTable[Invested],CorpusTable[Type],DashBoard!H10) -> 700000
A14: 💼 | B14: =SUMIFS(CorpusTable[Current Value],CorpusTable[Type],DashBoard!B10) -> 5015237.9 | D14: =SUMIFS(CorpusTable[Current Value],CorpusTable[Type],DashBoard!D10) -> 878605.98 | E14: =SUMIFS(CorpusTable[Current Value],CorpusTable[Type],DashBoard!E10) -> 1521019.5 | F14: =SUMIFS(CorpusTable[Current Value],CorpusTable[Type],DashBoard!F10) -> 3479947.6 | H14: =SUMIFS(CorpusTable[Current Value],CorpusTable[Type],DashBoard!H10) -> 1650000
A15: 💸 | B15: =SUMIFS(CorpusTable[Return],CorpusTable[Type],DashBoard!B10) -> 2186150.9 | D15: =SUMIFS(CorpusTable[Return],CorpusTable[Type],DashBoard!D10) -> 456167.98 | E15: =SUMIFS(CorpusTable[Return],CorpusTable[Type],DashBoard!E10) -> 480918.54 | F15: =SUMIFS(CorpusTable[Return],CorpusTable[Type],DashBoard!F10) -> 780847.64 | H15: =SUMIFS(CorpusTable[Return],CorpusTable[Type],DashBoard!H10) -> 950000
A16: % | B16: =SUMIFS(CorpusTable[Return%],CorpusTable[Type],DashBoard!B10) -> 1.5464654 | D16: =SUMIFS(CorpusTable[Return%],CorpusTable[Type],DashBoard!D10) -> 3.2641885 | E16: =SUMIFS(CorpusTable[Return%],CorpusTable[Type],DashBoard!E10) -> 0.46237677 | F16: =SUMIFS(CorpusTable[Return%],CorpusTable[Type],DashBoard!F10) -> 0.52474854 | H16: =SUMIFS(CorpusTable[Return%],CorpusTable[Type],DashBoard!H10) -> 1.3571429
B18: Expected | C18: 200000 | D18: 120000 | E18: 137000 | F18: 75000 | H18: 400000
B19: Month | C19: Income | D19: Expense | E19: Loan Repayment | F19: Investment | G19: Savings | H19: RBI Balance
B20: 45962 | C20: =_xlfn.IFNA(INDEX( IncomeTable[Total In Hand], MATCH(Table3[[#This Row],[Month]], IncomeTable[Month], 0) ),0) -> 360556 | D20: =_xlfn.IFNA(INDEX( ExpenseTable[Actual Expense], MATCH(Table3[[#This Row],[Month]], ExpenseTable[Month], 0) ),0) -> 76341 | E20: =_xlfn.IFNA(INDEX( LoanTable[Total Loan], MATCH(Table3[[#This Row],[Month]], LoanTable[Month], 0) ),0) -> 244200 | F20: =_xlfn.IFNA(INDEX( InvestmentTable[Total Investment], MATCH(Table3[[#This Row],[Month]], InvestmentTable[Entry Month], 0) ),0) -> 71670 | G20: =Table3[[#This Row],[Income]]-Table3[[#This Row],[Expense]]-Table3[[#This Row],[Loan Repayment]]-Table3[[#This Row],[Investment]] -> -31655 | H20: =_xlfn.IFNA(INDEX(RBITable[Transactions], MATCH(Table3[[#This Row],[Month]],RBITable[Month],0)),"") -> 82008
B21: 45992 | C21: =_xlfn.IFNA(INDEX( IncomeTable[Total In Hand], MATCH(Table3[[#This Row],[Month]], IncomeTable[Month], 0) ),0) -> 281023 | D21: =_xlfn.IFNA(INDEX( ExpenseTable[Actual Expense], MATCH(Table3[[#This Row],[Month]], ExpenseTable[Month], 0) ),0) -> 105100 | E21: =_xlfn.IFNA(INDEX( LoanTable[Total Loan], MATCH(Table3[[#This Row],[Month]], LoanTable[Month], 0) ),0) -> 124803 | F21: =_xlfn.IFNA(INDEX( InvestmentTable[Total Investment], MATCH(Table3[[#This Row],[Month]], InvestmentTable[Entry Month], 0) ),0) -> 86773 | G21: =Table3[[#This Row],[Income]]-Table3[[#This Row],[Expense]]-Table3[[#This Row],[Loan Repayment]]-Table3[[#This Row],[Investment]] -> -35653 | H21: =_xlfn.IFNA(INDEX(RBITable[Transactions], MATCH(Table3[[#This Row],[Month]],RBITable[Month],0)),"") -> 35985
B22: 46023 | C22: =_xlfn.IFNA(INDEX( IncomeTable[Total In Hand], MATCH(Table3[[#This Row],[Month]], IncomeTable[Month], 0) ),0) -> 256525 | D22: =_xlfn.IFNA(INDEX( ExpenseTable[Actual Expense], MATCH(Table3[[#This Row],[Month]], ExpenseTable[Month], 0) ),0) -> 121465 | E22: =_xlfn.IFNA(INDEX( LoanTable[Total Loan], MATCH(Table3[[#This Row],[Month]], LoanTable[Month], 0) ),0) -> 158488 | F22: =_xlfn.IFNA(INDEX( InvestmentTable[Total Investment], MATCH(Table3[[#This Row],[Month]], InvestmentTable[Entry Month], 0) ),0) -> -26320 | G22: =Table3[[#This Row],[Income]]-Table3[[#This Row],[Expense]]-Table3[[#This Row],[Loan Repayment]]-Table3[[#This Row],[Investment]] -> 2892 | H22: =_xlfn.IFNA(INDEX(RBITable[Transactions], MATCH(Table3[[#This Row],[Month]],RBITable[Month],0)),"") -> -10069
B23: 46054 | C23: =_xlfn.IFNA(INDEX( IncomeTable[Total In Hand], MATCH(Table3[[#This Row],[Month]], IncomeTable[Month], 0) ),0) -> 207702 | D23: =_xlfn.IFNA(INDEX( ExpenseTable[Actual Expense], MATCH(Table3[[#This Row],[Month]], ExpenseTable[Month], 0) ),0) -> 71006 | E23: =_xlfn.IFNA(INDEX( LoanTable[Total Loan], MATCH(Table3[[#This Row],[Month]], LoanTable[Month], 0) ),0) -> 154962 | F23: =_xlfn.IFNA(INDEX( InvestmentTable[Total Investment], MATCH(Table3[[#This Row],[Month]], InvestmentTable[Entry Month], 0) ),0) -> 105136 | G23: =Table3[[#This Row],[Income]]-Table3[[#This Row],[Expense]]-Table3[[#This Row],[Loan Repayment]]-Table3[[#This Row],[Investment]] -> -123402 | H23: =_xlfn.IFNA(INDEX(RBITable[Transactions], MATCH(Table3[[#This Row],[Month]],RBITable[Month],0)),"") -> -56151
B24: 46082 | C24: =_xlfn.IFNA(INDEX( IncomeTable[Total In Hand], MATCH(Table3[[#This Row],[Month]], IncomeTable[Month], 0) ),0) -> 263833 | D24: =_xlfn.IFNA(INDEX( ExpenseTable[Actual Expense], MATCH(Table3[[#This Row],[Month]], ExpenseTable[Month], 0) ),0) -> 113838 | E24: =_xlfn.IFNA(INDEX( LoanTable[Total Loan], MATCH(Table3[[#This Row],[Month]], LoanTable[Month], 0) ),0) -> 152098 | F24: =_xlfn.IFNA(INDEX( InvestmentTable[Total Investment], MATCH(Table3[[#This Row],[Month]], InvestmentTable[Entry Month], 0) ),0) -> 129873 | G24: =Table3[[#This Row],[Income]]-Table3[[#This Row],[Expense]]-Table3[[#This Row],[Loan Repayment]]-Table3[[#This Row],[Investment]] -> -131976 | H24: =_xlfn.IFNA(INDEX(RBITable[Transactions], MATCH(Table3[[#This Row],[Month]],RBITable[Month],0)),"") -> -102264
B25: 46113 | C25: =_xlfn.IFNA(INDEX( IncomeTable[Total In Hand], MATCH(Table3[[#This Row],[Month]], IncomeTable[Month], 0) ),0) -> 0 | D25: =_xlfn.IFNA(INDEX( ExpenseTable[Actual Expense], MATCH(Table3[[#This Row],[Month]], ExpenseTable[Month], 0) ),0) -> 0 | E25: =_xlfn.IFNA(INDEX( LoanTable[Total Loan], MATCH(Table3[[#This Row],[Month]], LoanTable[Month], 0) ),0) -> 0 | F25: =_xlfn.IFNA(INDEX( InvestmentTable[Total Investment], MATCH(Table3[[#This Row],[Month]], InvestmentTable[Entry Month], 0) ),0) -> 0 | G25: =Table3[[#This Row],[Income]]-Table3[[#This Row],[Expense]]-Table3[[#This Row],[Loan Repayment]]-Table3[[#This Row],[Investment]] -> 0 | H25: =_xlfn.IFNA(INDEX(RBITable[Transactions], MATCH(Table3[[#This Row],[Month]],RBITable[Month],0)),"") -> 0
B26: Total | C26: =SUBTOTAL(109,Table3[Income]) -> 1369639 | D26: =SUBTOTAL(109,Table3[Expense]) -> 487750 | E26: =SUBTOTAL(109,Table3[Loan Repayment]) -> 834551 | F26: =SUBTOTAL(109,Table3[Investment]) -> 367132 | G26: =SUBTOTAL(109,Table3[Savings]) -> -319794
B27: Avg | C27: =AVERAGEIF(Table3[Income],">0") -> 273927.8 | D27: =AVERAGEIF(Table3[Expense],">0") -> 97550 | E27: =AVERAGEIF(Table3[Loan Repayment],">0") -> 166910.2 | F27: =AVERAGEIF(Table3[Investment],">0") -> 98363 | G27: =AVERAGE(Table3[Savings]) -> -53299

Sheet Income
B2: Basic | C2: 110854
B3: Year | C3: Month | D3: Total In Hand | E3: Salary Credit | F3: NPS Deduction | G3: EPF Deduction | H3: EPF Loan Deduction | I3: Lease Phone Deduction | J3: Lease Vehcile Dedution | K3: Incentive Bonus | L3: Rati | M3: Family | N3: Investment Return | O3: Loan Return
B4: =TEXT(IncomeTable[[#This Row],[Month]],"YYYY") -> 2025 | C4: 45962 | D4: =SUM(IncomeTable[[#This Row],[Salary Credit]:[Loan Return]])-IncomeTable[[#This Row],[NPS Deduction]]-IncomeTable[[#This Row],[EPF Deduction]] -> 360556 | E4: 196352 | F4: 15515 | G4: 26604 | H4: 22170 | I4: 1920 | J4: 0 | K4: 140114 | L4: 0 | M4: 0 | N4: 0 | O4: 0
B5: =TEXT(IncomeTable[[#This Row],[Month]],"YYYY") -> 2025 | C5: 45992 | D5: =SUM(IncomeTable[[#This Row],[Salary Credit]:[Loan Return]])-IncomeTable[[#This Row],[NPS Deduction]]-IncomeTable[[#This Row],[EPF Deduction]] -> 281023 | E5: 196933 | F5: 15515 | G5: 26604 | H5: 22170 | I5: 1920 | J5: 0 | K5: 0 | L5: 0 | M5: 0 | N5: 60000 | O5: 0
B6: =TEXT(IncomeTable[[#This Row],[Month]],"YYYY") -> 2026 | C6: 46023 | D6: =SUM(IncomeTable[[#This Row],[Salary Credit]:[Loan Return]])-IncomeTable[[#This Row],[NPS Deduction]]-IncomeTable[[#This Row],[EPF Deduction]] -> 256525 | E6: 197435 | F6: 15515 | G6: 26604 | H6: 22170 | I6: 1920 | J6: 0 | K6: 0 | L6: 0 | M6: 0 | N6: 35000 | O6: 0
B7: =TEXT(IncomeTable[[#This Row],[Month]],"YYYY") -> 2026 | C7: 46054 | D7: =SUM(IncomeTable[[#This Row],[Salary Credit]:[Loan Return]])-IncomeTable[[#This Row],[NPS Deduction]]-IncomeTable[[#This Row],[EPF Deduction]] -> 207702 | E7: 158612 | F7: 15515 | G7: 26604 | H7: 22170 | I7: 1920 | J7: 25000 | K7: 0 | L7: 0 | M7: 0 | N7: 0 | O7: 0
B8: =TEXT(IncomeTable[[#This Row],[Month]],"YYYY") -> 2026 | C8: 46082 | D8: =SUM(IncomeTable[[#This Row],[Salary Credit]:[Loan Return]])-IncomeTable[[#This Row],[NPS Deduction]]-IncomeTable[[#This Row],[EPF Deduction]] -> 263833 | E8: =144815+8068 -> 152883 | F8: 15515 | G8: 26004 | H8: 22170 | I8: 1920 | J8: 25000 | K8: 0 | L8: 0 | M8: 0 | N8: =35000+26860 -> 61860 | O8: 0
B9: =TEXT(IncomeTable[[#This Row],[Month]],"YYYY") -> 2026 | C9: 46113 | D9: =SUM(IncomeTable[[#This Row],[Salary Credit]:[Loan Return]])-IncomeTable[[#This Row],[NPS Deduction]]-IncomeTable[[#This Row],[EPF Deduction]] -> 0
B10: Total | D10: =SUBTOTAL(109,IncomeTable[Total In Hand]) -> 1369639 | E10: =SUBTOTAL(109,IncomeTable[Salary Credit]) -> 902215 | F10: =SUBTOTAL(109,IncomeTable[NPS Deduction]) -> 77575 | G10: =SUBTOTAL(109,IncomeTable[EPF Deduction]) -> 132420 | H10: =SUBTOTAL(109,IncomeTable[EPF Loan Deduction]) -> 110850 | I10: =SUBTOTAL(109,IncomeTable[Lease Phone Deduction]) -> 9600 | J10: =SUBTOTAL(109,IncomeTable[Lease Vehcile Dedution]) -> 50000 | K10: =SUBTOTAL(109,IncomeTable[Incentive Bonus]) -> 140114 | L10: =SUBTOTAL(109,IncomeTable[Rati]) -> 0 | M10: =SUBTOTAL(109,IncomeTable[Family]) -> 0 | N10: =SUBTOTAL(109,IncomeTable[Investment Return]) -> 156860 | O10: =SUBTOTAL(109,IncomeTable[Loan Return]) -> 0
B11: Average | D11: =AVERAGE(IncomeTable[Total In Hand]) -> 228273.17 | E11: =AVERAGE(IncomeTable[Salary Credit]) -> 180443 | F11: =AVERAGE(IncomeTable[NPS Deduction]) -> 15515 | G11: =AVERAGE(IncomeTable[EPF Deduction]) -> 26484 | H11: =AVERAGE(IncomeTable[EPF Loan Deduction]) -> 22170 | I11: =AVERAGE(IncomeTable[Lease Phone Deduction]) -> 1920 | J11: =AVERAGE(IncomeTable[Lease Vehcile Dedution]) -> 10000 | K11: =AVERAGE(IncomeTable[Incentive Bonus]) -> 28022.8 | L11: =AVERAGE(IncomeTable[Rati]) -> 0 | M11: =AVERAGE(IncomeTable[Family]) -> 0 | N11: =AVERAGE(IncomeTable[Investment Return]) -> 31372 | O11: =AVERAGE(IncomeTable[Loan Return]) -> 0

Sheet Expenses
B2: Expected Yearly | C2: =SUM(E2:L2) -> 1466559 | D2: =12*D3 -> 2082996 | E2: =200000+50000 -> 250000 | F2: =25000+15000+20000 -> 60000 | G2: 720000 | H2: 150000 | I2: 120000 | J2: 60000 | K2: 60000 | L2: =_xlfn.CEILING.MATH(12*(BasicSalary*3.5%)) -> 46559
B3: Expected Monthly | C3: =SUM(E3:L3) -> 122214 | D3: =Loan!D3 -> 173583 | E3: =_xlfn.CEILING.MATH(E2/12) -> 20834 | F3: =_xlfn.CEILING.MATH(F2/12) -> 5000 | G3: =_xlfn.CEILING.MATH(G2/12) -> 60000 | H3: =_xlfn.CEILING.MATH(H2/12) -> 12500 | I3: =_xlfn.CEILING.MATH(I2/12) -> 10000 | J3: =_xlfn.CEILING.MATH(J2/12) -> 5000 | K3: =_xlfn.CEILING.MATH(K2/12) -> 5000 | L3: =_xlfn.CEILING.MATH(L2/12) -> 3880
B4: Month | C4: Actual Expense | D4: Loan EMI | E4: Kid | F4: Payments | G4: HouseHold | H4: Transport | I4: Family Care | J4: Shopping | K4: Luxary | L4: Support
B5: 45962 | C5: =SUM(ExpenseTable[[#This Row],[Kid]:[Support]]) -> 76341 | D5: =_xlfn.IFNA(INDEX( LoanTable[Total Loan], MATCH(ExpenseTable[[#This Row],[Month]], LoanTable[Month], 0) ),0) -> 244200 | E5: 2019 | F5: =1400+549+1100 -> 3049 | G5: =10000+8337+5080+3109+2386+1660 -> 30572 | H5: 11272 | I5: 5076 | J5: 14788 | K5: 4684 | L5: 4881
B6: 45992 | C6: =SUM(ExpenseTable[[#This Row],[Kid]:[Support]]) -> 105100 | D6: =_xlfn.IFNA(INDEX( LoanTable[Total Loan], MATCH(ExpenseTable[[#This Row],[Month]], LoanTable[Month], 0) ),0) -> 124803 | E6: 1193 | F6: =938+492+7494+199 -> 9123 | G6: =10260+7494+6341+500+3440+680+2047+827+99+335+1985+569+5600+5199+440+1450+1272+2494 -> 51032 | H6: =10500+6320+4480+5014+750-300 -> 26764 | I6: 3440 | J6: 2998 | K6: =2450+5900 -> 8350 | L6: 2200
B7: 46023 | C7: =SUM(ExpenseTable[[#This Row],[Kid]:[Support]]) -> 121465 | D7: =_xlfn.IFNA(INDEX( LoanTable[Total Loan], MATCH(ExpenseTable[[#This Row],[Month]], LoanTable[Month], 0) ),0) -> 158488 | E7: 845 | F7: =17950+4430+199+1112+2348 -> 26039 | G7: =15311+9591+6483+5350+5267 -> 42002 | H7: 32383 | I7: 13737 | J7: 445 | K7: =522+2894 -> 3416 | L7: 2598
B8: 46054 | C8: =SUM(ExpenseTable[[#This Row],[Kid]:[Support]]) -> 71006 | D8: =_xlfn.IFNA(INDEX( LoanTable[Total Loan], MATCH(ExpenseTable[[#This Row],[Month]], LoanTable[Month], 0) ),0) -> 154962 | E8: 1500 | F8: =800+199+150 -> 1149 | G8: =21960+2819+691 -> 25470 | H8: =7743+173 -> 7916 | I8: 24777 | J8: 6123 | K8: 2430 | L8: 1641
B9: 46082 | C9: =SUM(ExpenseTable[[#This Row],[Kid]:[Support]]) -> 113838 | D9: =_xlfn.IFNA(INDEX( LoanTable[Total Loan], MATCH(ExpenseTable[[#This Row],[Month]], LoanTable[Month], 0) ),0) -> 152098 | E9: 6097 | F9: =16551+199+35 -> 16785 | G9: =28951+9867+6513+5579+3003+3988 -> 57901 | H9: 1150 | I9: 6598 | J9: 20612 | K9: 2901 | L9: 1794
B10: 46113 | C10: =SUM(ExpenseTable[[#This Row],[Kid]:[Support]]) -> 0 | D10: =_xlfn.IFNA(INDEX( LoanTable[Total Loan], MATCH(ExpenseTable[[#This Row],[Month]], LoanTable[Month], 0) ),0) -> 0
B11: Total | C11: =SUBTOTAL(109,ExpenseTable[Actual Expense]) -> 487750 | D11: =SUBTOTAL(109,ExpenseTable[Loan EMI]) -> 834551 | E11: =SUBTOTAL(109,ExpenseTable[Kid]) -> 11654 | F11: =SUBTOTAL(109,ExpenseTable[Payments]) -> 56145 | G11: =SUBTOTAL(109,ExpenseTable[HouseHold]) -> 206977 | H11: =SUBTOTAL(109,ExpenseTable[Transport]) -> 79485 | I11: =SUBTOTAL(109,ExpenseTable[Family Care]) -> 53628 | J11: =SUBTOTAL(109,ExpenseTable[Shopping]) -> 44966 | K11: =SUBTOTAL(109,ExpenseTable[Luxary]) -> 21781 | L11: =SUBTOTAL(109,ExpenseTable[Support]) -> 13114
B12: Average | C12: =IFERROR(AVERAGE(ExpenseTable[Actual Expense]),0) -> 81291.667 | D12: =IFERROR(AVERAGE(ExpenseTable[Loan EMI]),0) -> 139091.83 | E12: =IFERROR(AVERAGE(ExpenseTable[Kid]),0) -> 2330.8 | F12: =IFERROR(AVERAGE(ExpenseTable[Payments]),0) -> 11229 | G12: =IFERROR(AVERAGE(ExpenseTable[HouseHold]),0) -> 41395.4 | H12: =IFERROR(AVERAGE(ExpenseTable[Transport]),0) -> 15897 | I12: =IFERROR(AVERAGE(ExpenseTable[Family Care]),0) -> 10725.6 | J12: =IFERROR(AVERAGE(ExpenseTable[Shopping]),0) -> 8993.2 | K12: =IFERROR(AVERAGE(ExpenseTable[Luxary]),0) -> 4356.2 | L12: =IFERROR(AVERAGE(ExpenseTable[Support]),0) -> 2622.8

Sheet Loan
B2: Opening Balance | E2: 4888992 | F2: 278700 | G2: 1574800 | H2: 471495 | I2: =1200000-(23000*5) -> 1085000 | J2: 120000 | K2: 89000 | L2: 56500 | M2: 50000 | N2: 75000 | O2: 135000 | P2: 40000 | R2: Balance | S2: Till 2026 | T2: EMI
B3: EMI | D3: =SUM(E3:P3) -> 173583 | E3: =IF(LoanTable[[#Totals],[Home Loan]]>0,18000) -> 18000 | F3: =IF(LoanTable[[#Totals],[Personal Loan]]>0,46450) -> 46450 | G3: =IF(LoanTable[[#Totals],[Car Loan]]>0,36800) -> 36800 | H3: =IF(LoanTable[[#Totals],[NBFC Loan (LIC)]]>0,2250) -> 2250 | I3: =IF(LoanTable[[#Totals],[EPF Loan]]>0,23000) -> 23000 | J3: =IF(LoanTable[[#Totals],[EPF Loan]]>0,13333) -> 13333 | K3: =IF(LoanTable[[#Totals],[Gadaget EMI]]>0,9000) -> 9000 | L3: =IF(LoanTable[[#Totals],[Credit Card EMI]]>0,12750) -> 12750 | M3: =IF(LoanTable[[#Totals],[Family loan]]>0,5000) -> 5000 | N3: =IF(LoanTable[[#Totals],[Credit Purchase]]>0,5000) -> 5000 | O3: =LoanTable[[#Totals],[Credit Card Due Till Nov -25 ]] -> 0 | P3: =IF(LoanTable[[#Totals],[Secret Partner]]>0,2000) -> 2000
B4: Year | C4: Month | D4: Total Loan | E4: Home Loan | F4: Personal Loan | G4: Car Loan | H4: NBFC Loan (LIC) | I4: EPF Loan | J4: Education Loan | K4: Gadaget EMI | L4: Credit Card EMI | M4: Family loan | N4: Credit Purchase | O4: Credit Card Due Till Nov -25 | P4: Secret Partner
B5: =TEXT(LoanTable[[#This Row],[Month]],"yyyy") -> 2025 | C5: 45962 | D5: =SUM(LoanTable[[#This Row],[Home Loan]:[Secret Partner]]) -> 244200 | E5: 18000 | F5: 46450 | G5: 0 | H5: 0 | I5: 23000 | J5: 0 | K5: 9000 | L5: 12750 | M5: 0 | N5: 0 | O5: 135000 | P5: 0
B6: =TEXT(LoanTable[[#This Row],[Month]],"yyyy") -> 2025 | C6: 45992 | D6: =SUM(LoanTable[[#This Row],[Home Loan]:[Secret Partner]]) -> 124803 | E6: 18000 | F6: 46450 | G6: 0 | H6: 15603 | I6: 23000 | J6: 0 | K6: 9000 | L6: 12750 | M6: 0 | N6: 0 | O6: 0 | P6: 0
B7: =TEXT(LoanTable[[#This Row],[Month]],"yyyy") -> 2026 | C7: 46023 | D7: =SUM(LoanTable[[#This Row],[Home Loan]:[Secret Partner]]) -> 158488 | E7: 18000 | F7: 46450 | G7: 0 | H7: 25640 | I7: 23000 | J7: 13648 | K7: 9000 | L7: 12750 | M7: 10000 | N7: 0 | O7: 0 | P7: 0
B8: =TEXT(LoanTable[[#This Row],[Month]],"yyyy") -> 2026 | C8: 46054 | D8: =SUM(LoanTable[[#This Row],[Home Loan]:[Secret Partner]]) -> 154962 | E8: 18000 | F8: 46450 | G8: 36800 | H8: 0 | I8: 23000 | J8: 13648 | K8: 9000 | L8: 8064 | M8: 0 | N8: 0 | O8: 0 | P8: 0
B9: =TEXT(LoanTable[[#This Row],[Month]],"yyyy") -> 2026 | C9: 46082 | D9: =SUM(LoanTable[[#This Row],[Home Loan]:[Secret Partner]]) -> 152098 | E9: 18000 | F9: 46450 | G9: 36800 | H9: 0 | I9: 23000 | J9: 13648 | K9: 9000 | L9: 5200 | M9: 0 | N9: 0 | O9: 0 | P9: 0
B10: =TEXT(LoanTable[[#This Row],[Month]],"yyyy") -> 2026 | C10: 46113 | D10: =SUM(LoanTable[[#This Row],[Home Loan]:[Secret Partner]]) -> 0
B11: =TEXT(LoanTable[[#This Row],[Month]],"yyyy") -> 1900 | D11: =SUM(LoanTable[[#This Row],[Home Loan]:[Secret Partner]]) -> 0
B12: Total | D12: =SUBTOTAL(109,LoanTable[Total Loan]) -> 834551 | E12: =E2-SUM(LoanTable[Home Loan]) -> 4798992 | F12: =F2-SUM(LoanTable[Personal Loan]) -> 46450 | G12: =G2-SUM(LoanTable[Car Loan]) -> 1501200 | H12: =H2-SUM(LoanTable[NBFC Loan (LIC)]) -> 430252 | I12: =I2-SUM(LoanTable[EPF Loan]) -> 970000 | K12: =K2-SUM(LoanTable[Gadaget EMI]) -> 44000 | L12: =L2-SUM(LoanTable[Credit Card EMI]) -> 4986 | M12: =M2-SUM(LoanTable[Family loan]) -> 40000 | N12: =N2-SUM(LoanTable[Credit Purchase]) -> 75000 | O12: =O2-SUM(LoanTable[Credit Card Due Till Nov -25 ]) -> 0 | P12: =P2-SUM(LoanTable[Secret Partner]) -> 40000
B13: Average | D13: =IFERROR(AVERAGE(LoanTable[Total Loan]),0) -> 119221.57 | E13: =IFERROR(AVERAGE(LoanTable[Home Loan]),0) -> 18000 | F13: =IFERROR(AVERAGE(LoanTable[Personal Loan]),0) -> 46450 | G13: =IFERROR(AVERAGE(LoanTable[Car Loan]),0) -> 14720 | H13: =IFERROR(AVERAGE(LoanTable[NBFC Loan (LIC)]),0) -> 8248.6 | I13: =IFERROR(AVERAGE(LoanTable[EPF Loan]),0) -> 23000 | K13: =IFERROR(AVERAGE(LoanTable[Gadaget EMI]),0) -> 9000 | L13: =IFERROR(AVERAGE(LoanTable[Credit Card EMI]),0) -> 10302.8 | M13: =IFERROR(AVERAGE(LoanTable[Family loan]),0) -> 2000 | N13: =IFERROR(AVERAGE(LoanTable[Credit Purchase]),0) -> 0 | O13: =IFERROR(AVERAGE(LoanTable[Credit Card Due Till Nov -25 ]),0) -> 27000 | P13: =IFERROR(AVERAGE(LoanTable[Secret Partner]),0) -> 0
H19: S.No | I19: Remaing Month | J19: Merchnat | K19: EMI Amount | L19: Tenure | M19: Total repayment | N19: Loan Distributor | O19: Remaining | P19: This Month | Q19: Remarks
H20: 1 | I20: =L20-DATEDIF(DATE(2025,11,1), TODAY(), "m") -> 13 | J20: LIC Intrest | K20: 27735 | L20: =13+DATEDIF(DATE(2025,11,1), TODAY(), "m") -> 18 | M20: =K20*L20 -> 499230 | N20: LIC | O20: =I20*K20 -> 360555 | P20: =IF(I20>0,K20) -> 27735
H21: 2 | I21: =L21-DATEDIF(DATE(2025,11,1), TODAY(), "m") -> 8 | J21: Home Loan | K21: 18000 | L21: 13 | M21: =K21*L21 -> 234000 | N21: Bhabhi | O21: =I21*K21 -> 144000 | P21: =IF(I21>0,K21) -> 18000
H22: 3 | I22: =L22-DATEDIF(DATE(2025,11,1), TODAY(), "m") -> 1 | J22: Personal Loan | K22: 46450 | L22: 6 | M22: =K22*L22 -> 278700 | N22: HSBC | O22: =I22*K22 -> 46450 | P22: =IF(I22>0,K22) -> 46450
H23: 4 | I23: =L23-DATEDIF(DATE(2025,11,1), TODAY(), "m") -> 8 | J23: NBFC Loan (LIC) | K23: 4250 | L23: 13 | M23: =K23*L23 -> 55250 | O23: =I23*K23 -> 34000 | P23: =IF(I23>0,K23) -> 4250
H24: 5 | I24: =L24-DATEDIF(DATE(2025,11,1), TODAY(), "m") -> 8 | J24: EPF Loan | K24: 23000 | L24: 13 | M24: =K24*L24 -> 299000 | N24: IDFC | O24: =I24*K24 -> 184000 | P24: =IF(I24>0,K24) -> 23000
H25: 6 | I25: =L25-DATEDIF(DATE(2025,11,1), TODAY(), "m") -> 1 | J25: Rati Iphone EMI | K25: =7000 -> 7000 | L25: 6 | M25: =K25*L25 -> 42000 | N25: SBI | O25: =I25*K25 -> 7000 | P25: =IF(I25>0,K25) -> 7000
H26: 7 | I26: =L26-DATEDIF(DATE(2025,11,1), TODAY(), "m") -> 8 | J26: My Iphone | K26: 2000 | L26: 13 | M26: =K26*L26 -> 26000 | N26: Salary | O26: =I26*K26 -> 16000 | P26: =IF(I26>0,K26) -> 2000
H27: 8 | I27: =L27-DATEDIF(DATE(2025,11,1), TODAY(), "m") -> 0 | J27: Orchid Hosptility | K27: 5200 | L27: 5 | M27: =K27*L27 -> 26000 | N27: AXIS Flipkart CC | O27: =I27*K27 -> 0 | P27: =IF(I27>0,K27) -> FALSE
H28: 9 | I28: =L28-DATEDIF(DATE(2025,11,1), TODAY(), "m") -> -2 | J28: MakeMytrip | K28: =2125 -> 2125 | L28: 3 | M28: =K28*L28 -> 6375 | O28: =I28*K28 -> -4250 | P28: =IF(I28>0,K28) -> FALSE | Q28: =SUM(P27:P31) -> 0
H29: 10 | I29: =L29-DATEDIF(DATE(2025,11,1), TODAY(), "m") -> -1 | J29: MakeMytrip | K29: =2691.99+172.51 -> 2864.5 | L29: 4 | M29: =K29*L29 -> 11458 | O29: =I29*K29 -> -2864.5 | P29: =IF(I29>0,K29) -> FALSE
H30: 11 | I30: =L30-DATEDIF(DATE(2025,11,1), TODAY(), "m") -> -2 | J30: MakeMytrip | K30: =1804+31 -> 1835 | L30: 3 | M30: =K30*L30 -> 5505 | O30: =I30*K30 -> -3670 | P30: =IF(I30>0,K30) -> FALSE
H31: 12 | I31: =L31-DATEDIF(DATE(2025,11,1), TODAY(), "m") -> -2 | J31: MakeMytrip | K31: =679+7 -> 686 | L31: 3 | M31: =K31*L31 -> 2058 | O31: =I31*K31 -> -1372 | P31: =IF(I31>0,K31) -> FALSE
H32: 13 | I32: =L32-DATEDIF(DATE(2025,11,1), TODAY(), "m") -> 10 | J32: Bhaiya | K32: 5000 | L32: =10+DATEDIF(DATE(2025,11,1), TODAY(), "m") -> 15 | M32: =K32*L32 -> 75000 | O32: =I32*K32 -> 50000 | P32: =IF(I32>0,K32) -> 5000
H33: 14 | I33: =L33-DATEDIF(DATE(2025,11,1), TODAY(), "m") -> 5 | J33: Abhishek Interior | K33: 15000 | L33: =5+DATEDIF(DATE(2025,11,1), TODAY(), "m") -> 10 | M33: =K33*L33 -> 150000 | O33: =I33*K33 -> 75000 | P33: =IF(I33>0,K33) -> 15000
H34: 15 | I34: =L34-DATEDIF(DATE(2025,11,1), TODAY(), "m") -> 12 | J34: Secret Partner | K34: 5000 | L34: =12+DATEDIF(DATE(2025,11,1), TODAY(), "m") -> 17 | M34: =K34*L34 -> 85000 | O34: =I34*K34 -> 60000 | P34: =IF(I34>0,K34) -> 5000
H35: 16 | I35: =L35-DATEDIF(DATE(2026,1,1), TODAY(), "m") -> 0 | J35: MakeMytrip | K35: =5200/3 -> 1733.3333 | L35: 3 | M35: =K35*L35 -> 5200 | N35: HSBC CC | O35: =I35*K35 -> 0 | P35: =IF(I35>0,K35) -> FALSE | Q35: Bomaby Trip
H36: 17 | I36: =L36-DATEDIF(DATE(2026,1,1), TODAY(), "m") -> 3 | J36: MakeMytrip | K36: 2000 | L36: 6 | M36: =K36*L36 -> 12000 | N36: AXIS Flipkart CC | O36: =I36*K36 -> 6000 | P36: =IF(I36>0,K36) -> 2000 | Q36: Mummy Flight Ticket
H37: 18 | I37: =L37-DATEDIF(DATE(2026,3,1), TODAY(), "m") -> 2 | J37: Flipkar | K37: 4000 | L37: 3 | M37: =K37*L37 -> 12000 | N37: AXIS Flipkart CC | O37: =I37*K37 -> 8000 | P37: =IF(I37>0,K37) -> 4000 | Q37: Didi Mobile
H38: 19 | I38: =L38-DATEDIF(DATE(2026,2,1), TODAY(), "m") -> 34 | J38: Car Loan | K38: 36800 | L38: 36 | M38: =K38*L38 -> 1324800 | N38: Salary | O38: =I38*K38 -> 1251200 | P38: =IF(I38>0,K38) -> 36800 | Q38: Car Loan
H39: 20 | I39: =L39-DATEDIF(DATE(2026,3,1), TODAY(), "m") -> 5 | J39: MakeMytrip | K39: 1900 | L39: 6 | M39: =K39*L39 -> 11400 | N39: HSBC CC | O39: =I39*K39 -> 9500 | P39: =IF(I39>0,K39) -> 1900 | Q39: Mummy Return Ticket
I40: Total | K40: =SUM(K20:K36) -> 169878.83 | L40: =SUM(L20:L36) -> 151 | M40: =SUM(M20:M36) -> 1812776 | N40: =SUM(N20:N36) -> 0 | O40: =SUM(O20:O36) -> 970848.5 | P40: =SUM(P20:P36) -> 155435

Sheet Investment
C2: Investment Quota | D2: ="Equity Limit : " -> Equity Limit : | E2: =_xlfn.FLOOR.MATH(InvestmentQuota*65%) -> 44513 | F2: ="Gold Limit : " -> Gold Limit : | I2: =_xlfn.FLOOR.MATH((InvestmentQuota*15%)) -> 10272 | J2: ="Fixed Return Limit : " -> Fixed Return Limit : | L2: =_xlfn.FLOOR.MATH(InvestmentQuota*20%) -> 13696 | M2: Real State | N2: 0
C3: =AVERAGE(IncomeTable[Total In Hand])*30% -> 68481.95 | D3: =E2*15% -> 6676.95 | E3: =E2*85% -> 37836.05 | F3: =I2*40% -> 4108.8 | G3: =I2*40% -> 4108.8 | H3: =I2*20% -> 2054.4 | I3: =I2*0% -> 0 | J3: =_xlfn.FLOOR.MATH(BasicSalary*24%) -> 26604 | K3: =_xlfn.FLOOR.MATH(BasicSalary*14%) -> 15519 | L3: 12500
C4: =3861068+(TotalMonth*InvestmentQuota) -> 4271959.7
B6: Entry Month | C6: Total Investment | D6: Stocks | E6: Mutual Fund | F6: Gold MF | G6: Gold ETF | H6: Gold | I6: SGB | J6: EPF | K6: NPS | L6: Sukanya Samriddhi | M6: Land | N6: Flat
B7: 45962 | C7: =SUM(InvestmentTable[[#This Row],[Stocks]:[Flat]]) -> 71670 | D7: =_xlfn.CEILING.MATH(SUMIFS(InvestTransactionTable[Invested Value],InvestTransactionTable[Type],"Stocks",InvestTransactionTable[Month],InvestmentTable[[#This Row],[Entry Month]])) -> 0 | E7: =_xlfn.CEILING.MATH(SUMIFS(InvestTransactionTable[Invested Value],InvestTransactionTable[Type],"Mutual Fund",InvestTransactionTable[Month],InvestmentTable[[#This Row],[Entry Month]])) -> 17055 | F7: =_xlfn.CEILING.MATH(SUMIFS(InvestTransactionTable[Invested Value],InvestTransactionTable[Type],"Gold MF",InvestTransactionTable[Month],InvestmentTable[[#This Row],[Entry Month]])) -> 0 | G7: =_xlfn.CEILING.MATH(SUMIFS(InvestTransactionTable[Invested Value],InvestTransactionTable[Type],"Gold ETF",InvestTransactionTable[Month],InvestmentTable[[#This Row],[Entry Month]])) -> 0 | H7: =_xlfn.CEILING.MATH(SUMIFS(InvestTransactionTable[Invested Value],InvestTransactionTable[Type],"Gold",InvestTransactionTable[Month],InvestmentTable[[#This Row],[Entry Month]])) -> 0 | I7: =_xlfn.CEILING.MATH(SUMIFS(InvestTransactionTable[Invested Value],InvestTransactionTable[Type],"Gold",InvestTransactionTable[Month],InvestmentTable[[#This Row],[Entry Month]])) -> 0 | J7: 26600 | K7: 15515 | L7: 12500 | M7: 0 | N7: 0
B8: 45992 | C8: =SUM(InvestmentTable[[#This Row],[Stocks]:[Flat]]) -> 86773 | D8: =12990+10000 -> 22990 | E8: =_xlfn.CEILING.MATH(SUMIFS(InvestTransactionTable[Invested Value],InvestTransactionTable[Type],"Mutual Fund",InvestTransactionTable[Month],InvestmentTable[[#This Row],[Entry Month]])) -> 7402 | F8: =_xlfn.CEILING.MATH(SUMIFS(InvestTransactionTable[Invested Value],InvestTransactionTable[Type],"Gold MF",InvestTransactionTable[Month],InvestmentTable[[#This Row],[Entry Month]])) -> 1766 | G8: =_xlfn.CEILING.MATH(SUMIFS(InvestTransactionTable[Invested Value],InvestTransactionTable[Type],"Gold ETF",InvestTransactionTable[Month],InvestmentTable[[#This Row],[Entry Month]])) -> 0 | H8: =_xlfn.CEILING.MATH(SUMIFS(InvestTransactionTable[Invested Value],InvestTransactionTable[Type],"Gold",InvestTransactionTable[Month],InvestmentTable[[#This Row],[Entry Month]])) -> 0 | I8: =_xlfn.CEILING.MATH(SUMIFS(InvestTransactionTable[Invested Value],InvestTransactionTable[Type],"Gold",InvestTransactionTable[Month],InvestmentTable[[#This Row],[Entry Month]])) -> 0 | J8: 26600 | K8: 15515 | L8: 12500 | M8: 0 | N8: 0
B9: 46023 | C9: =SUM(InvestmentTable[[#This Row],[Stocks]:[Flat]]) -> -26320 | D9: =575+5000+5000-200000 -> -189425 | E9: =_xlfn.CEILING.MATH(SUMIFS(InvestTransactionTable[Invested Value],InvestTransactionTable[Type],"Mutual Fund",InvestTransactionTable[Month],InvestmentTable[[#This Row],[Entry Month]])) -> 83993 | F9: =_xlfn.CEILING.MATH(SUMIFS(InvestTransactionTable[Invested Value],InvestTransactionTable[Type],"Gold MF",InvestTransactionTable[Month],InvestmentTable[[#This Row],[Entry Month]])) -> 6000 | G9: =_xlfn.CEILING.MATH(SUMIFS(InvestTransactionTable[Invested Value],InvestTransactionTable[Type],"Gold ETF",InvestTransactionTable[Month],InvestmentTable[[#This Row],[Entry Month]])) -> 19097 | H9: =_xlfn.CEILING.MATH(SUMIFS(InvestTransactionTable[Invested Value],InvestTransactionTable[Type],"Gold",InvestTransactionTable[Month],InvestmentTable[[#This Row],[Entry Month]])) -> 0 | I9: =_xlfn.CEILING.MATH(SUMIFS(InvestTransactionTable[Invested Value],InvestTransactionTable[Type],"Gold",InvestTransactionTable[Month],InvestmentTable[[#This Row],[Entry Month]])) -> 0 | J9: 26000 | K9: 15515 | L9: 12500 | M9: 0 | N9: 0
B10: 46054 | C10: =SUM(InvestmentTable[[#This Row],[Stocks]:[Flat]]) -> 105136 | D10: 0 | E10: =_xlfn.CEILING.MATH(SUMIFS(InvestTransactionTable[Invested Value],InvestTransactionTable[Type],"Mutual Fund",InvestTransactionTable[Month],InvestmentTable[[#This Row],[Entry Month]])) -> 35002 | F10: =_xlfn.CEILING.MATH(SUMIFS(InvestTransactionTable[Invested Value],InvestTransactionTable[Type],"Gold MF",InvestTransactionTable[Month],InvestmentTable[[#This Row],[Entry Month]])) -> 4000 | G10: =_xlfn.CEILING.MATH(SUMIFS(InvestTransactionTable[Invested Value],InvestTransactionTable[Type],"Gold ETF",InvestTransactionTable[Month],InvestmentTable[[#This Row],[Entry Month]])) -> 12119 | H10: =_xlfn.CEILING.MATH(SUMIFS(InvestTransactionTable[Invested Value],InvestTransactionTable[Type],"Gold",InvestTransactionTable[Month],InvestmentTable[[#This Row],[Entry Month]])) -> 0 | I10: =_xlfn.CEILING.MATH(SUMIFS(InvestTransactionTable[Invested Value],InvestTransactionTable[Type],"Gold",InvestTransactionTable[Month],InvestmentTable[[#This Row],[Entry Month]])) -> 0 | J10: 26000 | K10: 15515 | L10: 12500 | M10: 0 | N10: 0
B11: 46082 | C11: =SUM(InvestmentTable[[#This Row],[Stocks]:[Flat]]) -> 129873 | D11: =50000+10000+3000 -> 63000 | E11: =_xlfn.CEILING.MATH(SUMIFS(InvestTransactionTable[Invested Value],InvestTransactionTable[Type],"Mutual Fund",InvestTransactionTable[Month],InvestmentTable[[#This Row],[Entry Month]])) -> 2976 | F11: =_xlfn.CEILING.MATH(SUMIFS(InvestTransactionTable[Invested Value],InvestTransactionTable[Type],"Gold MF",InvestTransactionTable[Month],InvestmentTable[[#This Row],[Entry Month]])) -> 4000 | G11: =_xlfn.CEILING.MATH(SUMIFS(InvestTransactionTable[Invested Value],InvestTransactionTable[Type],"Gold ETF",InvestTransactionTable[Month],InvestmentTable[[#This Row],[Entry Month]])) -> 5882 | H11: =_xlfn.CEILING.MATH(SUMIFS(InvestTransactionTable[Invested Value],InvestTransactionTable[Type],"Gold",InvestTransactionTable[Month],InvestmentTable[[#This Row],[Entry Month]])) -> 0 | I11: =_xlfn.CEILING.MATH(SUMIFS(InvestTransactionTable[Invested Value],InvestTransactionTable[Type],"Gold",InvestTransactionTable[Month],InvestmentTable[[#This Row],[Entry Month]])) -> 0 | J11: 26000 | K11: 15515 | L11: 12500 | M11: 0 | N11: 0
B12: 46113 | C12: =SUM(InvestmentTable[[#This Row],[Stocks]:[Flat]]) -> 0 | E12: =_xlfn.CEILING.MATH(SUMIFS(InvestTransactionTable[Invested Value],InvestTransactionTable[Type],"Mutual Fund",InvestTransactionTable[Month],InvestmentTable[[#This Row],[Entry Month]])) -> 0 | F12: =_xlfn.CEILING.MATH(SUMIFS(InvestTransactionTable[Invested Value],InvestTransactionTable[Type],"Gold MF",InvestTransactionTable[Month],InvestmentTable[[#This Row],[Entry Month]])) -> 0 | G12: =_xlfn.CEILING.MATH(SUMIFS(InvestTransactionTable[Invested Value],InvestTransactionTable[Type],"Gold ETF",InvestTransactionTable[Month],InvestmentTable[[#This Row],[Entry Month]])) -> 0 | H12: =_xlfn.CEILING.MATH(SUMIFS(InvestTransactionTable[Invested Value],InvestTransactionTable[Type],"Gold",InvestTransactionTable[Month],InvestmentTable[[#This Row],[Entry Month]])) -> 0 | I12: =_xlfn.CEILING.MATH(SUMIFS(InvestTransactionTable[Invested Value],InvestTransactionTable[Type],"Gold",InvestTransactionTable[Month],InvestmentTable[[#This Row],[Entry Month]])) -> 0
B13: Total | C13: =SUBTOTAL(109,InvestmentTable[Total Investment]) -> 367132 | D13: =SUBTOTAL(109,InvestmentTable[Stocks]) -> -103435 | E13: =SUBTOTAL(109,InvestmentTable[Mutual Fund]) -> 146428 | F13: =SUBTOTAL(109,InvestmentTable[Gold MF]) -> 15766 | G13: =SUBTOTAL(109,InvestmentTable[Gold ETF]) -> 37098 | H13: =SUBTOTAL(109,InvestmentTable[Gold]) -> 0 | I13: =SUBTOTAL(109,InvestmentTable[SGB]) -> 0 | J13: =SUBTOTAL(109,InvestmentTable[EPF]) -> 131200 | K13: =SUBTOTAL(109,InvestmentTable[NPS]) -> 77575 | L13: =SUBTOTAL(109,InvestmentTable[Sukanya Samriddhi]) -> 62500 | M13: =SUBTOTAL(109,InvestmentTable[Land]) -> 0 | N13: =SUBTOTAL(109,InvestmentTable[Flat]) -> 0
B14: Average | C14: =IFERROR(AVERAGE(InvestmentTable[Total Investment]),0) -> 61188.667 | D14: =IFERROR(_xlfn.CEILING.MATH(AVERAGE(InvestmentTable[Stocks])),0) -> -20687 | E14: =IFERROR(_xlfn.CEILING.MATH(AVERAGE(InvestmentTable[Mutual Fund])),0) -> 24405 | F14: =IFERROR(_xlfn.CEILING.MATH(AVERAGE(InvestmentTable[Gold MF])),0) -> 2628 | G14: =IFERROR(_xlfn.CEILING.MATH(AVERAGE(InvestmentTable[Gold ETF])),0) -> 6183 | H14: =IFERROR(_xlfn.CEILING.MATH(AVERAGE(InvestmentTable[Gold])),0) -> 0 | I14: =IFERROR(_xlfn.CEILING.MATH(AVERAGE(InvestmentTable[SGB])),0) -> 0 | J14: =IFERROR(_xlfn.CEILING.MATH(AVERAGE(InvestmentTable[EPF])),0) -> 26240 | K14: =IFERROR(_xlfn.CEILING.MATH(AVERAGE(InvestmentTable[NPS])),0) -> 15515 | L14: =IFERROR(_xlfn.CEILING.MATH(AVERAGE(InvestmentTable[Sukanya Samriddhi])),0) -> 12500 | M14: =IFERROR(_xlfn.CEILING.MATH(AVERAGE(InvestmentTable[Land])),0) -> 0 | N14: =IFERROR(_xlfn.CEILING.MATH(AVERAGE(InvestmentTable[Flat])),0) -> 0

Sheet Corpus
B1: Corpus - 2 Crore Till Dec 2027
B3: Asset | C3: Type | D3: Invested Till Oct 25 | E3: Actual Till Oct-25 | F3: Profit Till Oct-25 | G3: Allocation % Till Oct 25 | H3: Return % Till Date | I3: Invested Since Nov-25 | J3: Allocation % | K3: Invested | L3: Current Value | M3: Return | N3: Return% | O3: Wallet
B4: Stocks | C4: Equity | D4: 2186094 | E4: 3800000 | F4: =CorpusTable[[#This Row],[Actual Till Oct-25]]-CorpusTable[[#This Row],[Invested Till Oct 25]] -> 1613906 | G4: =CorpusTable[[#This Row],[Invested Till Oct 25]]/CorpusTable[[#Totals],[Invested Till Oct 25]] -> 0.29850016 | H4: =IFERROR((CorpusTable[[#This Row],[Actual Till Oct-25]]-CorpusTable[[#This Row],[Invested Till Oct 25]])/CorpusTable[[#This Row],[Invested Till Oct 25]],0) -> 0.73826011 | I4: =InvestmentTable[[#Totals],[Stocks]] -> -103435 | J4: =CorpusTable[[#This Row],[Invested Since Nov-25]]/CorpusTable[[#Totals],[Invested Since Nov-25]] -> -0.2817379 | K4: =CorpusTable[[#This Row],[Invested Till Oct 25]]+CorpusTable[[#This Row],[Invested Since Nov-25]] -> 2082659 | L4: =SUMIFS(AllocationTable[CURRENT VALUE],AllocationTable[TYPE],CorpusTable[[#This Row],[Asset]])+CorpusTable[[#This Row],[Wallet]] -> 3690870 | M4: =CorpusTable[[#This Row],[Current Value]]-CorpusTable[[#This Row],[Invested]] -> 1608211 | N4: =IFERROR(CorpusTable[[#This Row],[Return]]/CorpusTable[[#This Row],[Invested]],"-") -> 0.7721912 | O4: 99
B5: Mutual Fund | C5: Equity | D5: 600000 | E5: 1225000 | F5: =CorpusTable[[#This Row],[Actual Till Oct-25]]-CorpusTable[[#This Row],[Invested Till Oct 25]] -> 625000 | G5: =CorpusTable[[#This Row],[Invested Till Oct 25]]/CorpusTable[[#Totals],[Invested Till Oct 25]] -> 0.081926988 | H5: =IFERROR((CorpusTable[[#This Row],[Actual Till Oct-25]]-CorpusTable[[#This Row],[Invested Till Oct 25]])/CorpusTable[[#This Row],[Invested Till Oct 25]],0) -> 1.0416667 | I5: =InvestmentTable[[#Totals],[Mutual Fund]] -> 146428 | J5: =CorpusTable[[#This Row],[Invested Since Nov-25]]/CorpusTable[[#Totals],[Invested Since Nov-25]] -> 0.39884292 | K5: =CorpusTable[[#This Row],[Invested Till Oct 25]]+CorpusTable[[#This Row],[Invested Since Nov-25]] -> 746428 | L5: =SUMIFS(AllocationTable[CURRENT VALUE],AllocationTable[TYPE],CorpusTable[[#This Row],[Asset]])+CorpusTable[[#This Row],[Wallet]] -> 1324367.9 | M5: =CorpusTable[[#This Row],[Current Value]]-CorpusTable[[#This Row],[Invested]] -> 577939.93 | N5: =IFERROR(CorpusTable[[#This Row],[Return]]/CorpusTable[[#This Row],[Invested]],"-") -> 0.77427419
B6: Sukanya Samriddhi | C6: Fixed Return | D6: 705400 | E6: 795391 | F6: =CorpusTable[[#This Row],[Actual Till Oct-25]]-CorpusTable[[#This Row],[Invested Till Oct 25]] -> 89991 | G6: =CorpusTable[[#This Row],[Invested Till Oct 25]]/CorpusTable[[#Totals],[Invested Till Oct 25]] -> 0.096318829 | H6: =IFERROR((CorpusTable[[#This Row],[Actual Till Oct-25]]-CorpusTable[[#This Row],[Invested Till Oct 25]])/CorpusTable[[#This Row],[Invested Till Oct 25]],0) -> 0.12757443 | I6: =InvestmentTable[[#Totals],[Sukanya Samriddhi]] -> 62500 | J6: =CorpusTable[[#This Row],[Invested Since Nov-25]]/CorpusTable[[#Totals],[Invested Since Nov-25]] -> 0.1702385 | K6: =CorpusTable[[#This Row],[Invested Till Oct 25]]+CorpusTable[[#This Row],[Invested Since Nov-25]] -> 767900 | L6: =SUMIFS(AllocationTable[CURRENT VALUE],AllocationTable[TYPE],CorpusTable[[#This Row],[Asset]])+CorpusTable[[#This Row],[Wallet]] -> 921405.24 | M6: =CorpusTable[[#This Row],[Current Value]]-CorpusTable[[#This Row],[Invested]] -> 153505.24 | N6: =IFERROR(CorpusTable[[#This Row],[Return]]/CorpusTable[[#This Row],[Invested]],"-") -> 0.19990264
B7: EPF/PPF | C7: Fixed Return | D7: 1800000 | E7: =2344530+100000+61306 -> 2505836 | F7: =CorpusTable[[#This Row],[Actual Till Oct-25]]-CorpusTable[[#This Row],[Invested Till Oct 25]] -> 705836 | G7: =CorpusTable[[#This Row],[Invested Till Oct 25]]/CorpusTable[[#Totals],[Invested Till Oct 25]] -> 0.24578096 | H7: =IFERROR((CorpusTable[[#This Row],[Actual Till Oct-25]]-CorpusTable[[#This Row],[Invested Till Oct 25]])/CorpusTable[[#This Row],[Invested Till Oct 25]],0) -> 0.39213111 | I7: =InvestmentTable[[#Totals],[EPF]] -> 131200 | J7: =CorpusTable[[#This Row],[Invested Since Nov-25]]/CorpusTable[[#Totals],[Invested Since Nov-25]] -> 0.35736465 | K7: =CorpusTable[[#This Row],[Invested Till Oct 25]]+CorpusTable[[#This Row],[Invested Since Nov-25]] -> 1931200 | L7: =SUMIFS(AllocationTable[CURRENT VALUE],AllocationTable[TYPE],CorpusTable[[#This Row],[Asset]])+CorpusTable[[#This Row],[Wallet]] -> 2558542.4 | M7: =CorpusTable[[#This Row],[Current Value]]-CorpusTable[[#This Row],[Invested]] -> 627342.4 | N7: =IFERROR(CorpusTable[[#This Row],[Return]]/CorpusTable[[#This Row],[Invested]],"-") -> 0.3248459
B8: NPS | C8: Retirement | D8: 962526 | E8: 1500788 | F8: =CorpusTable[[#This Row],[Actual Till Oct-25]]-CorpusTable[[#This Row],[Invested Till Oct 25]] -> 538262 | G8: =CorpusTable[[#This Row],[Invested Till Oct 25]]/CorpusTable[[#Totals],[Invested Till Oct 25]] -> 0.13142809 | H8: =IFERROR((CorpusTable[[#This Row],[Actual Till Oct-25]]-CorpusTable[[#This Row],[Invested Till Oct 25]])/CorpusTable[[#This Row],[Invested Till Oct 25]],0) -> 0.55921814 | I8: =InvestmentTable[[#Totals],[NPS]] -> 77575 | J8: =CorpusTable[[#This Row],[Invested Since Nov-25]]/CorpusTable[[#Totals],[Invested Since Nov-25]] -> 0.21130002 | K8: =CorpusTable[[#This Row],[Invested Till Oct 25]]+CorpusTable[[#This Row],[Invested Since Nov-25]] -> 1040101 | L8: =SUMIFS(AllocationTable[CURRENT VALUE],AllocationTable[TYPE],CorpusTable[[#This Row],[Asset]])+CorpusTable[[#This Row],[Wallet]] -> 1521019.5 | M8: =CorpusTable[[#This Row],[Current Value]]-CorpusTable[[#This Row],[Invested]] -> 480918.54 | N8: =IFERROR(CorpusTable[[#This Row],[Return]]/CorpusTable[[#This Row],[Invested]],"-") -> 0.46237677
B9: Gold MF | C9: Gold | D9: 29000 | E9: 43000 | F9: =CorpusTable[[#This Row],[Actual Till Oct-25]]-CorpusTable[[#This Row],[Invested Till Oct 25]] -> 14000 | G9: =CorpusTable[[#This Row],[Invested Till Oct 25]]/CorpusTable[[#Totals],[Invested Till Oct 25]] -> 0.0039598044 | H9: =IFERROR((CorpusTable[[#This Row],[Actual Till Oct-25]]-CorpusTable[[#This Row],[Invested Till Oct 25]])/CorpusTable[[#This Row],[Invested Till Oct 25]],0) -> 0.48275862 | I9: =InvestmentTable[[#Totals],[Gold MF]] -> 15766 | J9: =CorpusTable[[#This Row],[Invested Since Nov-25]]/CorpusTable[[#Totals],[Invested Since Nov-25]] -> 0.042943682 | K9: =CorpusTable[[#This Row],[Invested Till Oct 25]]+CorpusTable[[#This Row],[Invested Since Nov-25]] -> 44766 | L9: =SUMIFS(AllocationTable[CURRENT VALUE],AllocationTable[TYPE],CorpusTable[[#This Row],[Asset]])+CorpusTable[[#This Row],[Wallet]] -> 72019.929 | M9: =CorpusTable[[#This Row],[Current Value]]-CorpusTable[[#This Row],[Invested]] -> 27253.929 | N9: =IFERROR(CorpusTable[[#This Row],[Return]]/CorpusTable[[#This Row],[Invested]],"-") -> 0.60880867
B10: Gold ETF | C10: Gold | D10: 88324 | E10: 117000 | F10: =CorpusTable[[#This Row],[Actual Till Oct-25]]-CorpusTable[[#This Row],[Invested Till Oct 25]] -> 28676 | G10: =CorpusTable[[#This Row],[Invested Till Oct 25]]/CorpusTable[[#Totals],[Invested Till Oct 25]] -> 0.012060199 | H10: =IFERROR((CorpusTable[[#This Row],[Actual Till Oct-25]]-CorpusTable[[#This Row],[Invested Till Oct 25]])/CorpusTable[[#This Row],[Invested Till Oct 25]],0) -> 0.32466827 | I10: =InvestmentTable[[#Totals],[Gold ETF]] -> 37098 | J10: =CorpusTable[[#This Row],[Invested Since Nov-25]]/CorpusTable[[#Totals],[Invested Since Nov-25]] -> 0.10104812 | K10: =CorpusTable[[#This Row],[Invested Till Oct 25]]+CorpusTable[[#This Row],[Invested Since Nov-25]] -> 125422 | L10: =SUMIFS(AllocationTable[CURRENT VALUE],AllocationTable[TYPE],CorpusTable[[#This Row],[Asset]])+CorpusTable[[#This Row],[Wallet]] -> 179271.05 | M10: =CorpusTable[[#This Row],[Current Value]]-CorpusTable[[#This Row],[Invested]] -> 53849.05 | N10: =IFERROR(CorpusTable[[#This Row],[Return]]/CorpusTable[[#This Row],[Invested]],"-") -> 0.42934294
B11: Gold | C11: Gold | D11: =9500*5.5 -> 52250 | E11: =10500*5.5 -> 57750 | F11: =CorpusTable[[#This Row],[Actual Till Oct-25]]-CorpusTable[[#This Row],[Invested Till Oct 25]] -> 5500 | G11: =CorpusTable[[#This Row],[Invested Till Oct 25]]/CorpusTable[[#Totals],[Invested Till Oct 25]] -> 0.0071344752 | H11: =IFERROR((CorpusTable[[#This Row],[Actual Till Oct-25]]-CorpusTable[[#This Row],[Invested Till Oct 25]])/CorpusTable[[#This Row],[Invested Till Oct 25]],0) -> 0.10526316 | I11: =InvestmentTable[[#Totals],[Gold]] -> 0 | J11: =CorpusTable[[#This Row],[Invested Since Nov-25]]/CorpusTable[[#Totals],[Invested Since Nov-25]] -> 0 | K11: =CorpusTable[[#This Row],[Invested Till Oct 25]]+CorpusTable[[#This Row],[Invested Since Nov-25]] -> 52250 | L11: =SUMIFS(AllocationTable[CURRENT VALUE],AllocationTable[TYPE],CorpusTable[[#This Row],[Asset]])+CorpusTable[[#This Row],[Wallet]] -> 77055 | M11: =CorpusTable[[#This Row],[Current Value]]-CorpusTable[[#This Row],[Invested]] -> 24805 | N11: =IFERROR(CorpusTable[[#This Row],[Return]]/CorpusTable[[#This Row],[Invested]],"-") -> 0.47473684
B12: SGB | C12: Gold | D12: 200000 | E12: =36*12500 -> 450000 | F12: =CorpusTable[[#This Row],[Actual Till Oct-25]]-CorpusTable[[#This Row],[Invested Till Oct 25]] -> 250000 | G12: =CorpusTable[[#This Row],[Invested Till Oct 25]]/CorpusTable[[#Totals],[Invested Till Oct 25]] -> 0.027308996 | H12: =IFERROR((CorpusTable[[#This Row],[Actual Till Oct-25]]-CorpusTable[[#This Row],[Invested Till Oct 25]])/CorpusTable[[#This Row],[Invested Till Oct 25]],0) -> 1.25 | I12: =InvestmentTable[[#Totals],[SGB]] -> 0 | J12: =CorpusTable[[#This Row],[Invested Since Nov-25]]/CorpusTable[[#Totals],[Invested Since Nov-25]] -> 0 | K12: =CorpusTable[[#This Row],[Invested Till Oct 25]]+CorpusTable[[#This Row],[Invested Since Nov-25]] -> 200000 | L12: =SUMIFS(AllocationTable[CURRENT VALUE],AllocationTable[TYPE],CorpusTable[[#This Row],[Asset]])+CorpusTable[[#This Row],[Wallet]] -> 550260 | M12: =CorpusTable[[#This Row],[Current Value]]-CorpusTable[[#This Row],[Invested]] -> 350260 | N12: =IFERROR(CorpusTable[[#This Row],[Return]]/CorpusTable[[#This Row],[Invested]],"-") -> 1.7513
B13: Flat | C13: Real State | D13: 0 | E13: 0 | F13: =CorpusTable[[#This Row],[Actual Till Oct-25]]-CorpusTable[[#This Row],[Invested Till Oct 25]] -> 0 | G13: =CorpusTable[[#This Row],[Invested Till Oct 25]]/CorpusTable[[#Totals],[Invested Till Oct 25]] -> 0 | H13: =IFERROR((CorpusTable[[#This Row],[Actual Till Oct-25]]-CorpusTable[[#This Row],[Invested Till Oct 25]])/CorpusTable[[#This Row],[Invested Till Oct 25]],0) -> 0 | I13: =InvestmentTable[[#Totals],[Flat]] -> 0 | J13: =CorpusTable[[#This Row],[Invested Since Nov-25]]/CorpusTable[[#Totals],[Invested Since Nov-25]] -> 0 | K13: =CorpusTable[[#This Row],[Invested Till Oct 25]]+CorpusTable[[#This Row],[Invested Since Nov-25]] -> 0 | L13: =SUMIFS(AllocationTable[CURRENT VALUE],AllocationTable[TYPE],CorpusTable[[#This Row],[Asset]])+CorpusTable[[#This Row],[Wallet]] -> 0 | M13: =CorpusTable[[#This Row],[Current Value]]-CorpusTable[[#This Row],[Invested]] -> 0 | N13: =IFERROR(CorpusTable[[#This Row],[Return]]/CorpusTable[[#This Row],[Invested]],"-") -> -
B14: Land | C14: Real State | D14: 700000 | E14: =1100*1500 -> 1650000 | F14: =CorpusTable[[#This Row],[Actual Till Oct-25]]-CorpusTable[[#This Row],[Invested Till Oct 25]] -> 950000 | G14: =CorpusTable[[#This Row],[Invested Till Oct 25]]/CorpusTable[[#Totals],[Invested Till Oct 25]] -> 0.095581486 | H14: =IFERROR((CorpusTable[[#This Row],[Actual Till Oct-25]]-CorpusTable[[#This Row],[Invested Till Oct 25]])/CorpusTable[[#This Row],[Invested Till Oct 25]],0) -> 1.3571429 | I14: =InvestmentTable[[#Totals],[Land]] -> 0 | J14: =CorpusTable[[#This Row],[Invested Since Nov-25]]/CorpusTable[[#Totals],[Invested Since Nov-25]] -> 0 | K14: =CorpusTable[[#This Row],[Invested Till Oct 25]]+CorpusTable[[#This Row],[Invested Since Nov-25]] -> 700000 | L14: =SUMIFS(AllocationTable[CURRENT VALUE],AllocationTable[TYPE],CorpusTable[[#This Row],[Asset]])+CorpusTable[[#This Row],[Wallet]] -> 1650000 | M14: =CorpusTable[[#This Row],[Current Value]]-CorpusTable[[#This Row],[Invested]] -> 950000 | N14: =IFERROR(CorpusTable[[#This Row],[Return]]/CorpusTable[[#This Row],[Invested]],"-") -> 1.3571429
B15: Total | D15: =SUBTOTAL(109,CorpusTable[Invested Till Oct 25]) -> 7323594 | E15: =SUBTOTAL(109,CorpusTable[Actual Till Oct-25]) -> 12144765 | F15: =SUBTOTAL(109,CorpusTable[Profit Till Oct-25]) -> 4821171 | G15: =SUBTOTAL(109,CorpusTable[Allocation % Till Oct 25]) -> 1 | H15: =SUBTOTAL(101,CorpusTable[Return % Till Date]) -> 0.57988031 | I15: =SUBTOTAL(109,CorpusTable[Invested Since Nov-25]) -> 367132 | J15: =SUBTOTAL(109,CorpusTable[Allocation %]) -> 1 | K15: =SUBTOTAL(109,CorpusTable[Invested]) -> 7690726 | L15: =SUBTOTAL(109,CorpusTable[Current Value]) -> 12544811 | M15: =SUBTOTAL(109,CorpusTable[Return]) -> 4854085.1 | N15: =SUBTOTAL(101,CorpusTable[Return%]) -> 0.7154922
D17: Long Term | E17: 0.7 | F17: =C18*E17 -> 1916098.1
B18: Actual Stocks Allocation | C18: =SUMIF(AllocationTable[TYPE],"Stocks",AllocationTable[AA])+O4 -> 2737283
D19: Swing Trade | E19: 0.3 | F19: =C18*E19 -> 821184.9
B21: Month | C21: Transactions
B22: 45931 | C22: 128000
B23: 45962 | C23: =IFERROR(C22-INDEX( Table3[Month], MATCH(RBITable[[#This Row],[Month]], RBITable[Month], 0) ),0) -> 82008
B24: 45992 | C24: =IFERROR(C23-INDEX( Table3[Month], MATCH(RBITable[[#This Row],[Month]], RBITable[Month], 0) ),0) -> 35985
B25: 46023 | C25: =IFERROR(C24-INDEX( Table3[Month], MATCH(RBITable[[#This Row],[Month]], RBITable[Month], 0) ),0) -> -10069
B26: 46054 | C26: =IFERROR(C25-INDEX( Table3[Month], MATCH(RBITable[[#This Row],[Month]], RBITable[Month], 0) ),0) -> -56151
B27: 46082 | C27: =IFERROR(C26-INDEX( Table3[Month], MATCH(RBITable[[#This Row],[Month]], RBITable[Month], 0) ),0) -> -102264
B28: 46113 | C28: =IFERROR(C27-INDEX( Table3[Month], MATCH(RBITable[[#This Row],[Month]], RBITable[Month], 0) ),0) -> 0
B29: 46143 | C29: =IFERROR(C28-INDEX( Table3[Month], MATCH(RBITable[[#This Row],[Month]], RBITable[Month], 0) ),0) -> 0
B30: 46174 | C30: =IFERROR(C29-INDEX( Table3[Month], MATCH(RBITable[[#This Row],[Month]], RBITable[Month], 0) ),0) -> 0
B31: 46204 | C31: =IFERROR(C30-INDEX( Table3[Month], MATCH(RBITable[[#This Row],[Month]], RBITable[Month], 0) ),0) -> 0
B32: 46235 | C32: =IFERROR(C31-INDEX( Table3[Month], MATCH(RBITable[[#This Row],[Month]], RBITable[Month], 0) ),0) -> 0
B33: 46266 | C33: =IFERROR(C32-INDEX( Table3[Month], MATCH(RBITable[[#This Row],[Month]], RBITable[Month], 0) ),0) -> 0
B34: 46296 | C34: =IFERROR(C33-INDEX( Table3[Month], MATCH(RBITable[[#This Row],[Month]], RBITable[Month], 0) ),0) -> 0
... B36: 46357 | C36: =IFERROR(C35-INDEX( Table3[Month], MATCH(RBITable[[#This Row],[Month]], RBITable[Month], 0) ),0) -> 0

Sheet LongTerm
A1: TRADE | B1: TYPE | C1: SECTOR | D1: QNT | E1: AVG. | F1: LTP | G1: Available Quota | H1: PROFIT | I1: PROFIT% | J1: CURRENT VALUE | K1: EA% | L1: AA% | M1: EA | N1: AA | O1: MARKET CAP
A2: MCX | B2: Stocks | C2: =VLOOKUP(AllocationTable9[[#This Row],[TRADE]],AllocationTable[[TRADE]:[SECTOR]],2,0) -> FINANCIAL SERVICES | D2: 90 | E2: 708.17 | F2: =VLOOKUP(AllocationTable9[[#This Row],[TRADE]],LatestDump!A:I,4,0) -> 2669.4 | G2: =AllocationTable9[[#This Row],[EA]]-AllocationTable9[[#This Row],[AA]] -> 36264.7 | H2: =(AllocationTable9[[#This Row],[QNT]]*AllocationTable9[[#This Row],[LTP]])-(AllocationTable9[[#This Row],[QNT]]*AllocationTable9[[#This Row],[AVG.]]) -> 176510.7 | I2: =IFERROR(AllocationTable9[[#This Row],[PROFIT]]/AllocationTable9[[#This Row],[AA]],0) -> 2.7694339 | J2: =AllocationTable9[[#This Row],[QNT]]*AllocationTable9[[#This Row],[LTP]] -> 240246 | K2: =AllocationTable9[[#This Row],[EA]]/AllocationTable9[[#Totals],[EA]] -> 0.078125 | L2: =AllocationTable9[[#This Row],[AA]]/AllocationTable9[[#Totals],[AA]] -> 0.051913118 | M2: 100000 | N2: =AllocationTable9[[#This Row],[QNT]]*AllocationTable9[[#This Row],[AVG.]] -> 63735.3 | O2: MCAP
A3: IRFC | B3: Stocks | C3: =VLOOKUP(AllocationTable9[[#This Row],[TRADE]],AllocationTable[[TRADE]:[SECTOR]],2,0) -> ENGINEERING & CAPITAL GOODS | D3: 750 | E3: 36.22 | F3: =VLOOKUP(AllocationTable9[[#This Row],[TRADE]],LatestDump!A:I,4,0) -> 100.26 | G3: =AllocationTable9[[#This Row],[EA]]-AllocationTable9[[#This Row],[AA]] -> 22835 | H3: =(AllocationTable9[[#This Row],[QNT]]*AllocationTable9[[#This Row],[LTP]])-(AllocationTable9[[#This Row],[QNT]]*AllocationTable9[[#This Row],[AVG.]]) -> 48030 | I3: =IFERROR(AllocationTable9[[#This Row],[PROFIT]]/AllocationTable9[[#This Row],[AA]],0) -> 1.7680839 | J3: =AllocationTable9[[#This Row],[QNT]]*AllocationTable9[[#This Row],[LTP]] -> 75195 | K3: =AllocationTable9[[#This Row],[EA]]/AllocationTable9[[#Totals],[EA]] -> 0.0390625 | L3: =AllocationTable9[[#This Row],[AA]]/AllocationTable9[[#Totals],[AA]] -> 0.022126198 | M3: 50000 | N3: =AllocationTable9[[#This Row],[QNT]]*AllocationTable9[[#This Row],[AVG.]] -> 27165 | O3: LCAP
A4: ATHERENERG | B4: Stocks | C4: =VLOOKUP(AllocationTable9[[#This Row],[TRADE]],AllocationTable[[TRADE]:[SECTOR]],2,0) -> AUTO ANCILLARY | D4: 100 | E4: 315.91 | F4: =VLOOKUP(AllocationTable9[[#This Row],[TRADE]],LatestDump!A:I,4,0) -> 863.45 | G4: =AllocationTable9[[#This Row],[EA]]-AllocationTable9[[#This Row],[AA]] -> 18409 | H4: =(AllocationTable9[[#This Row],[QNT]]*AllocationTable9[[#This Row],[LTP]])-(AllocationTable9[[#This Row],[QNT]]*AllocationTable9[[#This Row],[AVG.]]) -> 54754 | I4: =IFERROR(AllocationTable9[[#This Row],[PROFIT]]/AllocationTable9[[#This Row],[AA]],0) -> 1.7332152 | J4: =AllocationTable9[[#This Row],[QNT]]*AllocationTable9[[#This Row],[LTP]] -> 86345 | K4: =AllocationTable9[[#This Row],[EA]]/AllocationTable9[[#Totals],[EA]] -> 0.0390625 | L4: =AllocationTable9[[#This Row],[AA]]/AllocationTable9[[#Totals],[AA]] -> 0.025731224 | M4: 50000 | N4: =AllocationTable9[[#This Row],[QNT]]*AllocationTable9[[#This Row],[AVG.]] -> 31591 | O4: SCAP
A5: VEDL | B5: Stocks | C5: =VLOOKUP(AllocationTable9[[#This Row],[TRADE]],AllocationTable[[TRADE]:[SECTOR]],2,0) -> METALS | D5: 200 | E5: 347 | F5: =VLOOKUP(AllocationTable9[[#This Row],[TRADE]],LatestDump!A:I,4,0) -> 745.15 | G5: =AllocationTable9[[#This Row],[EA]]-AllocationTable9[[#This Row],[AA]] -> -9400 | H5: =(AllocationTable9[[#This Row],[QNT]]*AllocationTable9[[#This Row],[LTP]])-(AllocationTable9[[#This Row],[QNT]]*AllocationTable9[[#This Row],[AVG.]]) -> 79630 | I5: =IFERROR(AllocationTable9[[#This Row],[PROFIT]]/AllocationTable9[[#This Row],[AA]],0) -> 1.1474063 | J5: =AllocationTable9[[#This Row],[QNT]]*AllocationTable9[[#This Row],[LTP]] -> 149030 | K5: =AllocationTable9[[#This Row],[EA]]/AllocationTable9[[#Totals],[EA]] -> 0.046875 | L5: =AllocationTable9[[#This Row],[AA]]/AllocationTable9[[#Totals],[AA]] -> 0.05652708 | M5: 60000 | N5: =AllocationTable9[[#This Row],[QNT]]*AllocationTable9[[#This Row],[AVG.]] -> 69400 | O5: LCAP
A6: ETERNAL | B6: Stocks | C6: =VLOOKUP(AllocationTable9[[#This Row],[TRADE]],AllocationTable[[TRADE]:[SECTOR]],2,0) -> IT | D6: 400 | E6: 136.07 | F6: =VLOOKUP(AllocationTable9[[#This Row],[TRADE]],LatestDump!A:I,4,0) -> 240 | G6: =AllocationTable9[[#This Row],[EA]]-AllocationTable9[[#This Row],[AA]] -> -4428 | H6: =(AllocationTable9[[#This Row],[QNT]]*AllocationTable9[[#This Row],[LTP]])-(AllocationTable9[[#This Row],[QNT]]*AllocationTable9[[#This Row],[AVG.]]) -> 41572 | I6: =IFERROR(AllocationTable9[[#This Row],[PROFIT]]/AllocationTable9[[#This Row],[AA]],0) -> 0.76379805 | J6: =AllocationTable9[[#This Row],[QNT]]*AllocationTable9[[#This Row],[LTP]] -> 96000 | K6: =AllocationTable9[[#This Row],[EA]]/AllocationTable9[[#Totals],[EA]] -> 0.0390625 | L6: =AllocationTable9[[#This Row],[AA]]/AllocationTable9[[#Totals],[AA]] -> 0.044332217 | M6: 50000 | N6: =AllocationTable9[[#This Row],[QNT]]*AllocationTable9[[#This Row],[AVG.]] -> 54428 | O6: LCAP
A7: BSE | B7: Stocks | C7: =VLOOKUP(AllocationTable9[[#This Row],[TRADE]],AllocationTable[[TRADE]:[SECTOR]],2,0) -> FINANCIAL SERVICES | D7: 125 | E7: 1863.78 | F7: =VLOOKUP(AllocationTable9[[#This Row],[TRADE]],LatestDump!A:I,4,0) -> 3281.2 | G7: =AllocationTable9[[#This Row],[EA]]-AllocationTable9[[#This Row],[AA]] -> -32972.5 | H7: =(AllocationTable9[[#This Row],[QNT]]*AllocationTable9[[#This Row],[LTP]])-(AllocationTable9[[#This Row],[QNT]]*AllocationTable9[[#This Row],[AVG.]]) -> 177177.5 | I7: =IFERROR(AllocationTable9[[#This Row],[PROFIT]]/AllocationTable9[[#This Row],[AA]],0) -> 0.76050821 | J7: =AllocationTable9[[#This Row],[QNT]]*AllocationTable9[[#This Row],[LTP]] -> 410150 | K7: =AllocationTable9[[#This Row],[EA]]/AllocationTable9[[#Totals],[EA]] -> 0.15625 | L7: =AllocationTable9[[#This Row],[AA]]/AllocationTable9[[#Totals],[AA]] -> 0.18975872 | M7: 200000 | N7: =AllocationTable9[[#This Row],[QNT]]*AllocationTable9[[#This Row],[AVG.]] -> 232972.5 | O7: LCAP
A8: M&M | B8: Stocks | C8: =VLOOKUP(AllocationTable9[[#This Row],[TRADE]],AllocationTable[[TRADE]:[SECTOR]],2,0) -> AUTO ANCILLARY | D8: 20 | E8: 1945.77 | F8: =VLOOKUP(AllocationTable9[[#This Row],[TRADE]],LatestDump!A:I,4,0) -> 3261.8 | G8: =AllocationTable9[[#This Row],[EA]]-AllocationTable9[[#This Row],[AA]] -> 11084.6 | H8: =(AllocationTable9[[#This Row],[QNT]]*AllocationTable9[[#This Row],[LTP]])-(AllocationTable9[[#This Row],[QNT]]*AllocationTable9[[#This Row],[AVG.]]) -> 26320.6 | I8: =IFERROR(AllocationTable9[[#This Row],[PROFIT]]/AllocationTable9[[#This Row],[AA]],0) -> 0.67635435 | J8: =AllocationTable9[[#This Row],[QNT]]*AllocationTable9[[#This Row],[LTP]] -> 65236 | K8: =AllocationTable9[[#This Row],[EA]]/AllocationTable9[[#Totals],[EA]] -> 0.0390625 | L8: =AllocationTable9[[#This Row],[AA]]/AllocationTable9[[#Totals],[AA]] -> 0.03169703 | M8: 50000 | N8: =AllocationTable9[[#This Row],[QNT]]*AllocationTable9[[#This Row],[AVG.]] -> 38915.4 | O8: LCAP
A9: HBLENGINE | B9: Stocks | C9: =VLOOKUP(AllocationTable9[[#This Row],[TRADE]],AllocationTable[[TRADE]:[SECTOR]],2,0) -> AUTO ANCILLARY | D9: 350 | E9: 455.79 | F9: =VLOOKUP(AllocationTable9[[#This Row],[TRADE]],LatestDump!A:I,4,0) -> 730.65 | G9: =AllocationTable9[[#This Row],[EA]]-AllocationTable9[[#This Row],[AA]] -> -9526.5 | H9: =(AllocationTable9[[#This Row],[QNT]]*AllocationTable9[[#This Row],[LTP]])-(AllocationTable9[[#This Row],[QNT]]*AllocationTable9[[#This Row],[AVG.]]) -> 96201 | I9: =IFERROR(AllocationTable9[[#This Row],[PROFIT]]/AllocationTable9[[#This Row],[AA]],0) -> 0.60304087 | J9: =AllocationTable9[[#This Row],[QNT]]*AllocationTable9[[#This Row],[LTP]] -> 255727.5 | K9: =AllocationTable9[[#This Row],[EA]]/AllocationTable9[[#Totals],[EA]] -> 0.1171875 | L9: =AllocationTable9[[#This Row],[AA]]/AllocationTable9[[#Totals],[AA]] -> 0.12993613 | M9: 150000 | N9: =AllocationTable9[[#This Row],[QNT]]*AllocationTable9[[#This Row],[AVG.]] -> 159526.5 | O9: MCAP
A10: ICICIAMC | B10: Stocks | C10: =VLOOKUP(AllocationTable9[[#This Row],[TRADE]],AllocationTable[[TRADE]:[SECTOR]],2,0) -> FINANCIAL SERVICES | D10: 6 | E10: 2165 | F10: =VLOOKUP(AllocationTable9[[#This Row],[TRADE]],LatestDump!A:I,4,0) -> 3390.2 | G10: =AllocationTable9[[#This Row],[EA]]-AllocationTable9[[#This Row],[AA]] -> 17010 | H10: =(AllocationTable9[[#This Row],[QNT]]*AllocationTable9[[#This Row],[LTP]])-(AllocationTable9[[#This Row],[QNT]]*AllocationTable9[[#This Row],[AVG.]]) -> 7351.2 | I10: =IFERROR(AllocationTable9[[#This Row],[PROFIT]]/AllocationTable9[[#This Row],[AA]],0) -> 0.56591224 | J10: =AllocationTable9[[#This Row],[QNT]]*AllocationTable9[[#This Row],[LTP]] -> 20341.2 | K10: =AllocationTable9[[#This Row],[EA]]/AllocationTable9[[#Totals],[EA]] -> 0.0234375 | L10: =AllocationTable9[[#This Row],[AA]]/AllocationTable9[[#Totals],[AA]] -> 0.010580501 | M10: 30000 | N10: =AllocationTable9[[#This Row],[QNT]]*AllocationTable9[[#This Row],[AVG.]] -> 12990 | O10: LCAP
